Workbook
Name Sunrisers_Harlington: Players!$A$52:$A$61
Name Mumbai_Indians_Imperial: Players!$A$12:$A$21
Name Crabtree_CC: Players!$A$2:$A$11
Name Redback_Rapscallions: Players!$A$42:$A$51
Name Take_Em_Deep: Players!$A$22:$A$31
Name Fable_6: Players!$A$32:$A$41

Sheet Instructions
A1: Imperial Super Sixes — Scorer's Spreadsheet
A3: How this works:
A4: 1. Fill in the Teams tab once, before the day (team names + which group they're in).
A5: 2. Fill in the Players tab once, before the day (one row per player + their team) — this
A6: turns the Player column in Batting/Bowling into a dropdown instead of free typing.
A7: 3. Fill in the Fixtures_Results tab: the running order is already sketched out below —
A8: edit team names for the knockout rounds once group results are known.
A9: 4. After each match, update its row in Fixtures_Results (Status + both teams' scores),
A10: then add one row per batter to Batting and one row per bowler to Bowling.
A11: 5. The website re-reads this spreadsheet automatically every few minutes. To force an
A12: immediate refresh, use the 'Run workflow' button on the GitHub Actions tab.
A14: Column notes:
... A32: Full setup guide: scraper/SUPER_SIXES_GUIDE.md in the website repository.

Sheet Fixtures_Results
A1: MatchNo | B1: Round | C1: Team1 | D1: Team2 | E1: BatTeam1 | F1: BatTeam2 | G1: Time | H1: Status | I1: BattedFirst | J1: Team1_Runs | K1: Team1_Wickets | L1: Team1_Overs | M1: Team2_Runs | N1: Team2_Wickets | O1: Team2_Overs | P1: Notes
A2: 1 | B2: Group A | C2: Take Em Deep | D2: Crabtree CC | E2: =IF(I2=1,C2,D2) -> Crabtree CC | F2: =if(I2=1,D2,C2) -> Take Em Deep | G2: 0.41666667 | H2: Scheduled | I2: 2 | J2: 56 | K2: 2 | L2: 5 | M2: 54 | N2: 5 | O2: 5
A3: 2 | B3: Group B | C3: Fable 6 | D3: Redback Rapscallions | E3: =IF(I3=1,C3,D3) -> Fable 6 | F3: =if(I3=1,D3,C3) -> Redback Rapscallions | G3: 0.4375 | H3: Scheduled | I3: 1
A4: 3 | B4: Group A | C4: Crabtree CC | D4: Mumbai Indians Imperial | E4: =IF(I4=1,C4,D4) -> Crabtree CC | F4: =if(I4=1,D4,C4) -> Mumbai Indians Imperial | G4: 0.45833333 | H4: Scheduled | I4: 1
A5: 4 | B5: Group B | C5: Fable 6 | D5: Sunrisers Harlington | E5: =IF(I5=1,C5,D5) -> Fable 6 | F5: =if(I5=1,D5,C5) -> Sunrisers Harlington | G5: 0.47916667 | H5: Scheduled | I5: 1
A6: 5 | B6: Group A | C6: Mumbai Indians Imperial | D6: Take Em Deep | E6: =IF(I6=1,C6,D6) -> Mumbai Indians Imperial | F6: =if(I6=1,D6,C6) -> Take Em Deep | G6: 0.5 | H6: Scheduled | I6: 1
A7: 6 | B7: Group B | C7: Redback Rapscallions | D7: Sunrisers Harlington | E7: =IF(I7=1,C7,D7) -> Redback Rapscallions | F7: =if(I7=1,D7,C7) -> Sunrisers Harlington | G7: 0.52083333 | H7: Scheduled | I7: 1
A8: 7 | B8: Semi Final 1 | C8: TBC | D8: TBC | E8: =IF(I8=1,C8,D8) -> TBC | F8: =if(I8=1,D8,C8) -> TBC | G8: 0.5625 | H8: Scheduled | I8: 1 | P8: Winner Group A v Runner-up Group B
A9: 8 | B9: Semi Final 2 | C9: TBC | D9: TBC | E9: =IF(I9=1,C9,D9) -> TBC | F9: =if(I9=1,D9,C9) -> TBC | G9: 0.60416667 | H9: Scheduled | I9: 1 | P9: Winner Group B v Runner-up Group A
A10: 9 | B10: Wooden Spoon | C10: TBC | D10: TBC | E10: =IF(I10=1,C10,D10) -> TBC | F10: =if(I10=1,D10,C10) -> TBC | G10: 0.625 | H10: Scheduled | I10: 1 | P10: Losers of the semi-finals
A11: 10 | B11: 3rd Place Playoff | C11: TBC | D11: TBC | E11: =IF(I11=1,C11,D11) -> TBC | F11: =if(I11=1,D11,C11) -> TBC | G11: 0.64583333 | H11: Scheduled | I11: 1 | P11: Winners of the semi-finals
A12: 11 | B12: Final | C12: TBC | D12: TBC | E12: =IF(I12=1,C12,D12) -> TBC | F12: =if(I12=1,D12,C12) -> TBC | G12: 0.66666667 | H12: Scheduled | I12: 1 | P12: 3rd-placed teams in each group

Sheet Batting
A1: MatchNo | B1: Innings | C1: Batting Team | D1: Bowling Team | E1: Player | F1: Runs | G1: Balls | H1: Fours | I1: Sixes | J1: HowOut | K1: Bowler | L1: Fielder
A2: 1 | B2: 2 | C2: {=iferror(INDEX(Fixtures_Results!$E$2:$F$12,MATCH($A2,Fixtures_Results!$A$2:$A$12,0),MATCH("BatTeam"&$B2,Fixtures_Results!$E$1:$F$1,0)),"")} -> Take Em Deep | D2: {=iferror(INDEX(Fixtures_Results!$E$2:$F$12,MATCH($A2,Fixtures_Results!$A$2:$A$12,0),MATCH("BatTeam"&2*1/$B2,Fixtures_Results!$E$1:$F$1,0)),"")} -> Crabtree CC | E2: Ro Shah | F2: 24 | G2: 15 | H2: 3 | I2: 1 | J2: not out | N2: {=iferror(transpose(INDIRECT(SUBSTITUTE($C2," ","_"))),"")} -> Deep | O2: Ro Shah | P2: Ro Shen | Q2: Kamaljit | R2: Dhyey | S2: Mithun | T2: Madhav | Z2: {=iferror(transpose(INDIRECT(SUBSTITUTE($D2," ","_"))),"")} -> Suhas | AA2: Sree | AB2: Sid | AC2: Joel | AD2: George | AE2: Matt G | AF2: BJ
A3: 1 | B3: 2 | C3: {=iferror(INDEX(Fixtures_Results!$E$2:$F$12,MATCH($A3,Fixtures_Results!$A$2:$A$12,0),MATCH("BatTeam"&$B3,Fixtures_Results!$E$1:$F$1,0)),"")} -> Take Em Deep | D3: {=iferror(INDEX(Fixtures_Results!$E$2:$F$12,MATCH($A3,Fixtures_Results!$A$2:$A$12,0),MATCH("BatTeam"&2*1/$B3,Fixtures_Results!$E$1:$F$1,0)),"")} -> Crabtree CC | E3: Dhyey | F3: 18 | G3: 12 | H3: 2 | I3: 0 | J3: ct | K3: Joel | L3: BJ | N3: {=iferror(transpose(INDIRECT(SUBSTITUTE($C3," ","_"))),"")} -> Deep | O3: Ro Shah | P3: Ro Shen | Q3: Kamaljit | R3: Dhyey | S3: Mithun | T3: Madhav | Z3: {=iferror(transpose(INDIRECT(SUBSTITUTE($D3," ","_"))),"")} -> Suhas | AA3: Sree | AB3: Sid | AC3: Joel | AD3: George | AE3: Matt G | AF3: BJ
A4: 1 | B4: 2 | C4: {=iferror(INDEX(Fixtures_Results!$E$2:$F$12,MATCH($A4,Fixtures_Results!$A$2:$A$12,0),MATCH("BatTeam"&$B4,Fixtures_Results!$E$1:$F$1,0)),"")} -> Take Em Deep | D4: {=iferror(INDEX(Fixtures_Results!$E$2:$F$12,MATCH($A4,Fixtures_Results!$A$2:$A$12,0),MATCH("BatTeam"&2*1/$B4,Fixtures_Results!$E$1:$F$1,0)),"")} -> Crabtree CC | E4: Madhav | F4: 0 | G4: 1 | H4: 0 | I4: 0 | J4: b | K4: Suhas | N4: {=iferror(transpose(INDIRECT(SUBSTITUTE($C4," ","_"))),"")} -> Deep | O4: Ro Shah | P4: Ro Shen | Q4: Kamaljit | R4: Dhyey | S4: Mithun | T4: Madhav | Z4: {=iferror(transpose(INDIRECT(SUBSTITUTE($D4," ","_"))),"")} -> Suhas | AA4: Sree | AB4: Sid | AC4: Joel | AD4: George | AE4: Matt G | AF4: BJ
A5: 1 | B5: 1 | C5: {=iferror(INDEX(Fixtures_Results!$E$2:$F$12,MATCH($A5,Fixtures_Results!$A$2:$A$12,0),MATCH("BatTeam"&$B5,Fixtures_Results!$E$1:$F$1,0)),"")} -> Crabtree CC | D5: {=iferror(INDEX(Fixtures_Results!$E$2:$F$12,MATCH($A5,Fixtures_Results!$A$2:$A$12,0),MATCH("BatTeam"&2*1/$B5,Fixtures_Results!$E$1:$F$1,0)),"")} -> Take Em Deep | E5: Sree | N5: {=iferror(transpose(INDIRECT(SUBSTITUTE($C5," ","_"))),"")} -> Suhas | O5: Sree | P5: Sid | Q5: Joel | R5: George | S5: Matt G | T5: BJ | Z5: {=iferror(transpose(INDIRECT(SUBSTITUTE($D5," ","_"))),"")} -> Deep | AA5: Ro Shah | AB5: Ro Shen | AC5: Kamaljit | AD5: Dhyey | AE5: Mithun | AF5: Madhav
A6: 1 | B6: 1 | C6: {=iferror(INDEX(Fixtures_Results!$E$2:$F$12,MATCH($A6,Fixtures_Results!$A$2:$A$12,0),MATCH("BatTeam"&$B6,Fixtures_Results!$E$1:$F$1,0)),"")} -> Crabtree CC | D6: {=iferror(INDEX(Fixtures_Results!$E$2:$F$12,MATCH($A6,Fixtures_Results!$A$2:$A$12,0),MATCH("BatTeam"&2*1/$B6,Fixtures_Results!$E$1:$F$1,0)),"")} -> Take Em Deep | E6: Sree | N6: {=iferror(transpose(INDIRECT(SUBSTITUTE($C6," ","_"))),"")} -> Suhas | O6: Sree | P6: Sid | Q6: Joel | R6: George | S6: Matt G | T6: BJ | Z6: {=iferror(transpose(INDIRECT(SUBSTITUTE($D6," ","_"))),"")} -> Deep | AA6: Ro Shah | AB6: Ro Shen | AC6: Kamaljit | AD6: Dhyey | AE6: Mithun | AF6: Madhav
A7: 2 | B7: 1 | C7: {=iferror(INDEX(Fixtures_Results!$E$2:$F$12,MATCH($A7,Fixtures_Results!$A$2:$A$12,0),MATCH("BatTeam"&$B7,Fixtures_Results!$E$1:$F$1,0)),"")} -> Fable 6 | D7: {=iferror(INDEX(Fixtures_Results!$E$2:$F$12,MATCH($A7,Fixtures_Results!$A$2:$A$12,0),MATCH("BatTeam"&2*1/$B7,Fixtures_Results!$E$1:$F$1,0)),"")} -> Redback Rapscallions | E7: Het | N7: {=iferror(transpose(INDIRECT(SUBSTITUTE($C7," ","_"))),"")} -> Himanshu | O7: Het | P7: Henil | Q7: Shivannk | R7: Darshil | S7: Shivit | Z7: {=iferror(transpose(INDIRECT(SUBSTITUTE($D7," ","_"))),"")} -> Deano | AA7: Vik | AB7: Hogan | AC7: Lizzie | AD7: Ach | AE7: Chaz
A8: 2 | B8: 2 | C8: {=iferror(INDEX(Fixtures_Results!$E$2:$F$12,MATCH($A8,Fixtures_Results!$A$2:$A$12,0),MATCH("BatTeam"&$B8,Fixtures_Results!$E$1:$F$1,0)),"")} -> Redback Rapscallions | D8: {=iferror(INDEX(Fixtures_Results!$E$2:$F$12,MATCH($A8,Fixtures_Results!$A$2:$A$12,0),MATCH("BatTeam"&2*1/$B8,Fixtures_Results!$E$1:$F$1,0)),"")} -> Fable 6 | E8: Deano | K8: Himanshu | N8: {=iferror(transpose(INDIRECT(SUBSTITUTE($C8," ","_"))),"")} -> Deano | O8: Vik | P8: Hogan | Q8: Lizzie | R8: Ach | S8: Chaz | Z8: {=iferror(transpose(INDIRECT(SUBSTITUTE($D8," ","_"))),"")} -> Himanshu | AA8: Het | AB8: Henil | AC8: Shivannk | AD8: Darshil | AE8: Shivit
A9: 3 | B9: 1 | C9: {=iferror(INDEX(Fixtures_Results!$E$2:$F$12,MATCH($A9,Fixtures_Results!$A$2:$A$12,0),MATCH("BatTeam"&$B9,Fixtures_Results!$E$1:$F$1,0)),"")} -> Crabtree CC | D9: {=iferror(INDEX(Fixtures_Results!$E$2:$F$12,MATCH($A9,Fixtures_Results!$A$2:$A$12,0),MATCH("BatTeam"&2*1/$B9,Fixtures_Results!$E$1:$F$1,0)),"")} -> Mumbai Indians Imperial | E9: Suhas | F9: 24 | G9: 12 | H9: 1 | I9: 2 | J9: b | K9: James H | N9: {=iferror(transpose(INDIRECT(SUBSTITUTE($C9," ","_"))),"")} -> Suhas | O9: Sree | P9: Sid | Q9: Joel | R9: George | S9: Matt G | T9: BJ | Z9: {=iferror(transpose(INDIRECT(SUBSTITUTE($D9," ","_"))),"")} -> James H | AA9: Ameya | AB9: Sheth | AC9: Ashish | AD9: Ish | AE9: Haider
A10: 3 | B10: 2 | C10: {=iferror(INDEX(Fixtures_Results!$E$2:$F$12,MATCH($A10,Fixtures_Results!$A$2:$A$12,0),MATCH("BatTeam"&$B10,Fixtures_Results!$E$1:$F$1,0)),"")} -> Mumbai Indians Imperial | D10: {=iferror(INDEX(Fixtures_Results!$E$2:$F$12,MATCH($A10,Fixtures_Results!$A$2:$A$12,0),MATCH("BatTeam"&2*1/$B10,Fixtures_Results!$E$1:$F$1,0)),"")} -> Crabtree CC | E10: James H | F10: 0 | G10: 1 | J10: hw | K10: Sree | N10: {=iferror(transpose(INDIRECT(SUBSTITUTE($C10," ","_"))),"")} -> James H | O10: Ameya | P10: Sheth | Q10: Ashish | R10: Ish | S10: Haider | Z10: {=iferror(transpose(INDIRECT(SUBSTITUTE($D10," ","_"))),"")} -> Suhas | AA10: Sree | AB10: Sid | AC10: Joel | AD10: George | AE10: Matt G | AF10: BJ
C11: {=iferror(INDEX(Fixtures_Results!$E$2:$F$12,MATCH($A11,Fixtures_Results!$A$2:$A$12,0),MATCH("BatTeam"&$B11,Fixtures_Results!$E$1:$F$1,0)),"")} | D11: {=iferror(INDEX(Fixtures_Results!$E$2:$F$12,MATCH($A11,Fixtures_Results!$A$2:$A$12,0),MATCH("BatTeam"&2*1/$B11,Fixtures_Results!$E$1:$F$1,0)),"")} | N11: {=iferror(transpose(INDIRECT(SUBSTITUTE($C11," ","_"))),"")} | Z11: {=iferror(transpose(INDIRECT(SUBSTITUTE($D11," ","_"))),"")}
C12: {=iferror(INDEX(Fixtures_Results!$E$2:$F$12,MATCH($A12,Fixtures_Results!$A$2:$A$12,0),MATCH("BatTeam"&$B12,Fixtures_Results!$E$1:$F$1,0)),"")} | D12: {=iferror(INDEX(Fixtures_Results!$E$2:$F$12,MATCH($A12,Fixtures_Results!$A$2:$A$12,0),MATCH("BatTeam"&2*1/$B12,Fixtures_Results!$E$1:$F$1,0)),"")} | N12: {=iferror(transpose(INDIRECT(SUBSTITUTE($C12," ","_"))),"")} | Z12: {=iferror(transpose(INDIRECT(SUBSTITUTE($D12," ","_"))),"")}
C13: {=iferror(INDEX(Fixtures_Results!$E$2:$F$12,MATCH($A13,Fixtures_Results!$A$2:$A$12,0),MATCH("BatTeam"&$B13,Fixtures_Results!$E$1:$F$1,0)),"")} | D13: {=iferror(INDEX(Fixtures_Results!$E$2:$F$12,MATCH($A13,Fixtures_Results!$A$2:$A$12,0),MATCH("BatTeam"&2*1/$B13,Fixtures_Results!$E$1:$F$1,0)),"")} | N13: {=iferror(transpose(INDIRECT(SUBSTITUTE($C13," ","_"))),"")} | Z13: {=iferror(transpose(INDIRECT(SUBSTITUTE($D13," ","_"))),"")}
C14: {=iferror(INDEX(Fixtures_Results!$E$2:$F$12,MATCH($A14,Fixtures_Results!$A$2:$A$12,0),MATCH("BatTeam"&$B14,Fixtures_Results!$E$1:$F$1,0)),"")} | D14: {=iferror(INDEX(Fixtures_Results!$E$2:$F$12,MATCH($A14,Fixtures_Results!$A$2:$A$12,0),MATCH("BatTeam"&2*1/$B14,Fixtures_Results!$E$1:$F$1,0)),"")} | N14: {=iferror(transpose(INDIRECT(SUBSTITUTE($C14," ","_"))),"")} | Z14: {=iferror(transpose(INDIRECT(SUBSTITUTE($D14," ","_"))),"")}
C15: {=iferror(INDEX(Fixtures_Results!$E$2:$F$12,MATCH($A15,Fixtures_Results!$A$2:$A$12,0),MATCH("BatTeam"&$B15,Fixtures_Results!$E$1:$F$1,0)),"")} | D15: {=iferror(INDEX(Fixtures_Results!$E$2:$F$12,MATCH($A15,Fixtures_Results!$A$2:$A$12,0),MATCH("BatTeam"&2*1/$B15,Fixtures_Results!$E$1:$F$1,0)),"")} | N15: {=iferror(transpose(INDIRECT(SUBSTITUTE($C15," ","_"))),"")} | Z15: {=iferror(transpose(INDIRECT(SUBSTITUTE($D15," ","_"))),"")}
C16: {=iferror(INDEX(Fixtures_Results!$E$2:$F$12,MATCH($A16,Fixtures_Results!$A$2:$A$12,0),MATCH("BatTeam"&$B16,Fixtures_Results!$E$1:$F$1,0)),"")} | D16: {=iferror(INDEX(Fixtures_Results!$E$2:$F$12,MATCH($A16,Fixtures_Results!$A$2:$A$12,0),MATCH("BatTeam"&2*1/$B16,Fixtures_Results!$E$1:$F$1,0)),"")} | N16: {=iferror(transpose(INDIRECT(SUBSTITUTE($C16," ","_"))),"")} | Z16: {=iferror(transpose(INDIRECT(SUBSTITUTE($D16," ","_"))),"")}
C17: {=iferror(INDEX(Fixtures_Results!$E$2:$F$12,MATCH($A17,Fixtures_Results!$A$2:$A$12,0),MATCH("BatTeam"&$B17,Fixtures_Results!$E$1:$F$1,0)),"")} | D17: {=iferror(INDEX(Fixtures_Results!$E$2:$F$12,MATCH($A17,Fixtures_Results!$A$2:$A$12,0),MATCH("BatTeam"&2*1/$B17,Fixtures_Results!$E$1:$F$1,0)),"")} | N17: {=iferror(transpose(INDIRECT(SUBSTITUTE($C17," ","_"))),"")} | Z17: {=iferror(transpose(INDIRECT(SUBSTITUTE($D17," ","_"))),"")}
C18: {=iferror(INDEX(Fixtures_Results!$E$2:$F$12,MATCH($A18,Fixtures_Results!$A$2:$A$12,0),MATCH("BatTeam"&$B18,Fixtures_Results!$E$1:$F$1,0)),"")} | D18: {=iferror(INDEX(Fixtures_Results!$E$2:$F$12,MATCH($A18,Fixtures_Results!$A$2:$A$12,0),MATCH("BatTeam"&2*1/$B18,Fixtures_Results!$E$1:$F$1,0)),"")} | N18: {=iferror(transpose(INDIRECT(SUBSTITUTE($C18," ","_"))),"")} | Z18: {=iferror(transpose(INDIRECT(SUBSTITUTE($D18," ","_"))),"")}
C19: {=iferror(INDEX(Fixtures_Results!$E$2:$F$12,MATCH($A19,Fixtures_Results!$A$2:$A$12,0),MATCH("BatTeam"&$B19,Fixtures_Results!$E$1:$F$1,0)),"")} | D19: {=iferror(INDEX(Fixtures_Results!$E$2:$F$12,MATCH($A19,Fixtures_Results!$A$2:$A$12,0),MATCH("BatTeam"&2*1/$B19,Fixtures_Results!$E$1:$F$1,0)),"")} | N19: {=iferror(transpose(INDIRECT(SUBSTITUTE($C19," ","_"))),"")} | Z19: {=iferror(transpose(INDIRECT(SUBSTITUTE($D19," ","_"))),"")}
C20: {=iferror(INDEX(Fixtures_Results!$E$2:$F$12,MATCH($A20,Fixtures_Results!$A$2:$A$12,0),MATCH("BatTeam"&$B20,Fixtures_Results!$E$1:$F$1,0)),"")} | D20: {=iferror(INDEX(Fixtures_Results!$E$2:$F$12,MATCH($A20,Fixtures_Results!$A$2:$A$12,0),MATCH("BatTeam"&2*1/$B20,Fixtures_Results!$E$1:$F$1,0)),"")} | N20: {=iferror(transpose(INDIRECT(SUBSTITUTE($C20," ","_"))),"")} | Z20: {=iferror(transpose(INDIRECT(SUBSTITUTE($D20," ","_"))),"")}
C21: {=iferror(INDEX(Fixtures_Results!$E$2:$F$12,MATCH($A21,Fixtures_Results!$A$2:$A$12,0),MATCH("BatTeam"&$B21,Fixtures_Results!$E$1:$F$1,0)),"")} | D21: {=iferror(INDEX(Fixtures_Results!$E$2:$F$12,MATCH($A21,Fixtures_Results!$A$2:$A$12,0),MATCH("BatTeam"&2*1/$B21,Fixtures_Results!$E$1:$F$1,0)),"")} | N21: {=iferror(transpose(INDIRECT(SUBSTITUTE($C21," ","_"))),"")} | Z21: {=iferror(transpose(INDIRECT(SUBSTITUTE($D21," ","_"))),"")}
C22: {=iferror(INDEX(Fixtures_Results!$E$2:$F$12,MATCH($A22,Fixtures_Results!$A$2:$A$12,0),MATCH("BatTeam"&$B22,Fixtures_Results!$E$1:$F$1,0)),"")} | D22: {=iferror(INDEX(Fixtures_Results!$E$2:$F$12,MATCH($A22,Fixtures_Results!$A$2:$A$12,0),MATCH("BatTeam"&2*1/$B22,Fixtures_Results!$E$1:$F$1,0)),"")} | N22: {=iferror(transpose(INDIRECT(SUBSTITUTE($C22," ","_"))),"")} | Z22: {=iferror(transpose(INDIRECT(SUBSTITUTE($D22," ","_"))),"")}
... C300: {=iferror(INDEX(Fixtures_Results!$E$2:$F$12,MATCH($A300,Fixtures_Results!$A$2:$A$12,0),MATCH("BatTeam"&$B300,Fixtures_Results!$E$1:$F$1,0)),"")} | D300: {=iferror(INDEX(Fixtures_Results!$E$2:$F$12,MATCH($A300,Fixtures_Results!$A$2:$A$12,0),MATCH("BatTeam"&2*1/$B300,Fixtures_Results!$E$1:$F$1,0)),"")} | N300: {=iferror(transpose(INDIRECT(SUBSTITUTE($C300," ","_"))),"")} | Z300: {=iferror(transpose(INDIRECT(SUBSTITUTE($D300," ","_"))),"")}

Sheet Bowling
A1: MatchNo | B1: Innings | C1: Bowling Team | D1: Bowler | E1: Overs | F1: Maidens | G1: Runs | H1: Wickets
A2: 1 | B2: 1 | C2: {=iferror(INDEX(Fixtures_Results!$E$2:$F$12,MATCH($A2,Fixtures_Results!$A$2:$A$12,0),MATCH("BatTeam"&2*1/$B2,Fixtures_Results!$E$1:$F$1,0)),"")} -> Take Em Deep | D2: Deep | E2: 1 | F2: 0 | G2: 24 | H2: 2 | M2: {=iferror(transpose(INDIRECT(SUBSTITUTE($C2," ","_"))),"")} -> Deep | N2: Ro Shah | O2: Ro Shen | P2: Kamaljit | Q2: Dhyey | R2: Mithun | S2: Madhav
A3: 1 | B3: 2 | C3: {=iferror(INDEX(Fixtures_Results!$E$2:$F$12,MATCH($A3,Fixtures_Results!$A$2:$A$12,0),MATCH("BatTeam"&2*1/$B3,Fixtures_Results!$E$1:$F$1,0)),"")} -> Crabtree CC | D3: Sree | E3: 1 | F3: 0 | G3: 5 | H3: 4 | M3: {=iferror(transpose(INDIRECT(SUBSTITUTE($C3," ","_"))),"")} -> Suhas | N3: Sree | O3: Sid | P3: Joel | Q3: George | R3: Matt G | S3: BJ
A4: 3 | B4: 1 | C4: {=iferror(INDEX(Fixtures_Results!$E$2:$F$12,MATCH($A4,Fixtures_Results!$A$2:$A$12,0),MATCH("BatTeam"&2*1/$B4,Fixtures_Results!$E$1:$F$1,0)),"")} -> Mumbai Indians Imperial | D4: James H | M4: {=iferror(transpose(INDIRECT(SUBSTITUTE($C4," ","_"))),"")} -> James H | N4: Ameya | O4: Sheth | P4: Ashish | Q4: Ish | R4: Haider
C5: {=iferror(INDEX(Fixtures_Results!$E$2:$F$12,MATCH($A5,Fixtures_Results!$A$2:$A$12,0),MATCH("BatTeam"&2*1/$B5,Fixtures_Results!$E$1:$F$1,0)),"")} | M5: {=iferror(transpose(INDIRECT(SUBSTITUTE($C5," ","_"))),"")}
C6: {=iferror(INDEX(Fixtures_Results!$E$2:$F$12,MATCH($A6,Fixtures_Results!$A$2:$A$12,0),MATCH("BatTeam"&2*1/$B6,Fixtures_Results!$E$1:$F$1,0)),"")} | M6: {=iferror(transpose(INDIRECT(SUBSTITUTE($C6," ","_"))),"")}
C7: {=iferror(INDEX(Fixtures_Results!$E$2:$F$12,MATCH($A7,Fixtures_Results!$A$2:$A$12,0),MATCH("BatTeam"&2*1/$B7,Fixtures_Results!$E$1:$F$1,0)),"")} | M7: {=iferror(transpose(INDIRECT(SUBSTITUTE($C7," ","_"))),"")}
C8: {=iferror(INDEX(Fixtures_Results!$E$2:$F$12,MATCH($A8,Fixtures_Results!$A$2:$A$12,0),MATCH("BatTeam"&2*1/$B8,Fixtures_Results!$E$1:$F$1,0)),"")} | M8: {=iferror(transpose(INDIRECT(SUBSTITUTE($C8," ","_"))),"")}
C9: {=iferror(INDEX(Fixtures_Results!$E$2:$F$12,MATCH($A9,Fixtures_Results!$A$2:$A$12,0),MATCH("BatTeam"&2*1/$B9,Fixtures_Results!$E$1:$F$1,0)),"")} | M9: {=iferror(transpose(INDIRECT(SUBSTITUTE($C9," ","_"))),"")}
C10: {=iferror(INDEX(Fixtures_Results!$E$2:$F$12,MATCH($A10,Fixtures_Results!$A$2:$A$12,0),MATCH("BatTeam"&2*1/$B10,Fixtures_Results!$E$1:$F$1,0)),"")} | M10: {=iferror(transpose(INDIRECT(SUBSTITUTE($C10," ","_"))),"")}
C11: {=iferror(INDEX(Fixtures_Results!$E$2:$F$12,MATCH($A11,Fixtures_Results!$A$2:$A$12,0),MATCH("BatTeam"&2*1/$B11,Fixtures_Results!$E$1:$F$1,0)),"")} | M11: {=iferror(transpose(INDIRECT(SUBSTITUTE($C11," ","_"))),"")}
C12: {=iferror(INDEX(Fixtures_Results!$E$2:$F$12,MATCH($A12,Fixtures_Results!$A$2:$A$12,0),MATCH("BatTeam"&2*1/$B12,Fixtures_Results!$E$1:$F$1,0)),"")} | M12: {=iferror(transpose(INDIRECT(SUBSTITUTE($C12," ","_"))),"")}
C13: {=iferror(INDEX(Fixtures_Results!$E$2:$F$12,MATCH($A13,Fixtures_Results!$A$2:$A$12,0),MATCH("BatTeam"&2*1/$B13,Fixtures_Results!$E$1:$F$1,0)),"")} | M13: {=iferror(transpose(INDIRECT(SUBSTITUTE($C13," ","_"))),"")}
C14: {=iferror(INDEX(Fixtures_Results!$E$2:$F$12,MATCH($A14,Fixtures_Results!$A$2:$A$12,0),MATCH("BatTeam"&2*1/$B14,Fixtures_Results!$E$1:$F$1,0)),"")} | M14: {=iferror(transpose(INDIRECT(SUBSTITUTE($C14," ","_"))),"")}
C15: {=iferror(INDEX(Fixtures_Results!$E$2:$F$12,MATCH($A15,Fixtures_Results!$A$2:$A$12,0),MATCH("BatTeam"&2*1/$B15,Fixtures_Results!$E$1:$F$1,0)),"")} | M15: {=iferror(transpose(INDIRECT(SUBSTITUTE($C15," ","_"))),"")}
C16: {=iferror(INDEX(Fixtures_Results!$E$2:$F$12,MATCH($A16,Fixtures_Results!$A$2:$A$12,0),MATCH("BatTeam"&2*1/$B16,Fixtures_Results!$E$1:$F$1,0)),"")} | M16: {=iferror(transpose(INDIRECT(SUBSTITUTE($C16," ","_"))),"")}
... C300: {=iferror(INDEX(Fixtures_Results!$E$2:$F$12,MATCH($A300,Fixtures_Results!$A$2:$A$12,0),MATCH("BatTeam"&2*1/$B300,Fixtures_Results!$E$1:$F$1,0)),"")} | M300: {=iferror(transpose(INDIRECT(SUBSTITUTE($C300," ","_"))),"")}

Sheet Players
A1: Player | B1: Team
A2: Suhas | B2: Crabtree CC
A3: Sree | B3: Crabtree CC
A4: Sid | B4: Crabtree CC
A5: Joel | B5: Crabtree CC
A6: George | B6: Crabtree CC
A7: Matt G | B7: Crabtree CC
A8: BJ | B8: Crabtree CC
B9: Crabtree CC
B10: Crabtree CC
B11: Crabtree CC
A12: James H | B12: Mumbai Indians Imperial
A13: Ameya | B13: Mumbai Indians Imperial
A14: Sheth | B14: Mumbai Indians Imperial
A15: Ashish | B15: Mumbai Indians Imperial
A16: Ish | B16: Mumbai Indians Imperial
A17: Haider | B17: Mumbai Indians Imperial
B18: Mumbai Indians Imperial
B19: Mumbai Indians Imperial
B20: Mumbai Indians Imperial
B21: Mumbai Indians Imperial
A22: Deep | B22: Take Em Deep
A23: Ro Shah | B23: Take Em Deep
A24: Ro Shen | B24: Take Em Deep
A25: Kamaljit | B25: Take Em Deep
A26: Dhyey | B26: Take Em Deep
A27: Mithun | B27: Take Em Deep
A28: Madhav | B28: Take Em Deep
B29: Take Em Deep
B30: Take Em Deep
B31: Take Em Deep
A32: Himanshu | B32: Fable 6
A33: Het | B33: Fable 6
A34: Henil | B34: Fable 6
A35: Shivannk | B35: Fable 6
A36: Darshil | B36: Fable 6
A37: Shivit | B37: Fable 6
B38: Fable 6
B39: Fable 6
B40: Fable 6
...

Sheet Teams
A1: Team | B1: Group
A2: Crabtree CC | B2: A
A3: Mumbai Indians Imperial | B3: A
A4: Take Em Deep | B4: A
A5: Fable 6 | B5: B
A6: Redback Rapscallions | B6: B
A7: Sunrisers Harlington | B7: B
A8: TBC
